{
  "libzmq5":
  [
    {
      "reason_to_ignore": "The current version is marked as a fix version in the CVE notes, and this is the latest version.",
      "description": "\n It was discovered that ZeroMQ incorrectly handled certain application metadata.\n A remote attacker could use this issue to cause ZeroMQ to crash, or possibly\n execute arbitrary code.",
      "vulnerability_id": "CVE-2019-13132",
      "name": "CVE-2019-13132",
      "package_name": "libzmq5",
      "package_details":
      {
        "file_path": null,
        "name": "libzmq5",
        "package_manager": "OS",
        "version": "4.3.2",
        "release": "2ubuntu1"
      },
      "remediation":
      {
        "recommendation":
        {
          "text": "None Provided"
        }
      },
      "cvss_v3_score": 9.8,
      "cvss_v30_score": 0,
      "cvss_v31_score": 9.8,
      "cvss_v2_score": 7.5,
      "cvss_v3_severity": "CRITICAL",
      "source_url": "https://people.canonical.com/~ubuntu-security/cve/2019/CVE-2019-13132.html",
      "source": "UBUNTU_CVE",
      "severity": "HIGH",
      "status": "ACTIVE",
      "title": "CVE-2019-13132 - libzmq5"
    }
  ],
  "scipy":
  [
    {
      "reason_to_ignore": "Temporarily ignoring to fix CRITICALs",
      "description": "A use-after-free issue was discovered in Py_FindObjects() function in SciPy versions prior to 1.8.0. NOTE: the vendor and discoverer indicate that this is not a security issue.",
      "vulnerability_id": "CVE-2023-29824",
      "name": "CVE-2023-29824",
      "package_name": "scipy",
      "package_details":
      {
        "file_path": "opt/llvm-project/libcxx/utils/google-benchmark/requirements.txt",
        "name": "scipy",
        "package_manager": "PIP",
        "version": "1.5.4",
        "release": null
      },
      "remediation":
      {
        "recommendation":
        {
          "text": "None Provided"
        }
      },
      "cvss_v3_score": 9.8,
      "cvss_v30_score": 0,
      "cvss_v31_score": 9.8,
      "cvss_v2_score": 0,
      "cvss_v3_severity": "CRITICAL",
      "source_url": "https://nvd.nist.gov/vuln/detail/CVE-2023-29824",
      "source": "NVD",
      "severity": "CRITICAL",
      "status": "ACTIVE",
      "title": "CVE-2023-29824 - scipy"
    }
  ],
  "transformers":
  [
    {
      "reason_to_ignore": "Need guidance from HF team on how to upgrade as it's breaking the image. Temporarily ignoring to patch other CVEs.",
      "description": "\n Insecure Temporary File in GitHub repository huggingface/transformers prior to 4.30.0..",
      "vulnerability_id": "CVE-2023-2800",
      "name": "CVE-2023-2800",
      "package_name": "transformers",
      "package_details":
      {
        "file_path": null,
        "name": "transformers",
        "package_manager": "PYTHONPKG",
        "version": "4.26.0",
        "release": ""
      },
      "remediation":
      {
        "recommendation":
        {
          "text": "Update transformers to 4.30.0."
        }
      },
      "cvss_v3_score": 4.7,
      "cvss_v30_score": 4.7,
      "cvss_v31_score": 4.7,
      "cvss_v2_score": 4.7,
      "cvss_v3_severity": "MEDIUM",
      "source_url": "https://nvd.nist.gov/vuln/detail/CVE-2023-2800",
      "source": "NVD",
      "severity": "MEDIUM",
      "status": "ACTIVE",
      "title": "CVE-2023-2800 - transformers"
    },
    {
      "description": "Deserialization of Untrusted Data in GitHub repository huggingface/transformers prior to 4.36.",
      "vulnerability_id": "CVE-2023-6730",
      "name": "CVE-2023-6730",
      "package_name": "transformers",
      "package_details":
      {
        "file_path": "opt/conda/lib/python3.10/site-packages/transformers-4.28.1.dist-info/METADATA",
        "name": "transformers",
        "package_manager": "PYTHONPKG",
        "version": "4.28.1",
        "release": null
      },
      "remediation":
      {
        "recommendation":
        {
          "text": "None Provided"
        }
      },
      "cvss_v3_score": 8.8,
      "cvss_v30_score": 0.0,
      "cvss_v31_score": 8.8,
      "cvss_v2_score": 0.0,
      "cvss_v3_severity": "HIGH",
      "source_url": "https://nvd.nist.gov/vuln/detail/CVE-2023-6730",
      "source": "NVD",
      "severity": "HIGH",
      "status": "ACTIVE",
      "title": "CVE-2023-6730 - transformers",
      "reason_to_ignore": "Need guidance from HF team on how to upgrade as it's breaking the image. Temporarily ignoring to patch other CVEs."
    },
    {
      "description": "Deserialization of Untrusted Data in GitHub repository huggingface/transformers prior to 4.36.",
      "vulnerability_id": "CVE-2023-7018",
      "name": "CVE-2023-7018",
      "package_name": "transformers",
      "package_details":
      {
        "file_path": "opt/conda/lib/python3.10/site-packages/transformers-4.28.1.dist-info/METADATA",
        "name": "transformers",
        "package_manager": "PYTHONPKG",
        "version": "4.28.1",
        "release": null
      },
      "remediation":
      {
        "recommendation":
        {
          "text": "None Provided"
        }
      },
      "cvss_v3_score": 7.8,
      "cvss_v30_score": 0.0,
      "cvss_v31_score": 7.8,
      "cvss_v2_score": 0.0,
      "cvss_v3_severity": "HIGH",
      "source_url": "https://nvd.nist.gov/vuln/detail/CVE-2023-7018",
      "source": "NVD",
      "severity": "HIGH",
      "status": "ACTIVE",
      "title": "CVE-2023-7018 - transformers",
      "reason_to_ignore": "Need guidance from HF team on how to upgrade as it's breaking the image. Temporarily ignoring to patch other CVEs."
    }
  ],
  "linux":
  [
    {
      "reason_to_ignore": "Temporarily ignoring to fix CRITICALs",
      "description": "\n Alon Zahavi discovered that the NVMe-oF/TCP subsystem in the Linux kernel\n did not properly handle queue initialization failures in certain\n situations, leading to a use-after-free vulnerability. A remote attacker\n could use this to cause a denial of service (system crash) or possibly\n execute arbitrary code.",
      "vulnerability_id": "CVE-2023-5178",
      "name": "CVE-2023-5178",
      "package_name": "linux",
      "package_details":
      {
        "file_path": null,
        "name": "linux",
        "package_manager": "OS",
        "version": "5.4.0",
        "release": "167.184"
      },
      "remediation":
      {
        "recommendation":
        {
          "text": "None Provided"
        }
      },
      "cvss_v3_score": 8.8,
      "cvss_v30_score": 0,
      "cvss_v31_score": 8.8,
      "cvss_v2_score": 0,
      "cvss_v3_severity": "HIGH",
      "source_url": "https://people.canonical.com/~ubuntu-security/cve/2023/CVE-2023-5178.html",
      "source": "UBUNTU_CVE",
      "severity": "HIGH",
      "status": "ACTIVE",
      "title": "CVE-2023-5178 - linux"
    }
  ]
}