{
  "libzmq5": [
    {
      "reason_to_ignore": "The current version is marked as a fix version in the CVE notes, and this is the latest version.",
      "description": "\n It was discovered that ZeroMQ incorrectly handled certain application metadata.\n A remote attacker could use this issue to cause ZeroMQ to crash, or possibly\n execute arbitrary code.",
      "vulnerability_id": "CVE-2019-13132",
      "name": "CVE-2019-13132",
      "package_name": "libzmq5",
      "package_details": {
        "file_path": null,
        "name": "libzmq5",
        "package_manager": "OS",
        "version": "4.3.2",
        "release": "2ubuntu1"
      },
      "remediation": {
        "recommendation": {
          "text": "None Provided"
        }
      },
      "cvss_v3_score": 9.8,
      "cvss_v30_score": 0,
      "cvss_v31_score": 9.8,
      "cvss_v2_score": 7.5,
      "cvss_v3_severity": "CRITICAL",
      "source_url": "https://people.canonical.com/~ubuntu-security/cve/2019/CVE-2019-13132.html",
      "source": "UBUNTU_CVE",
      "severity": "HIGH",
      "status": "ACTIVE",
      "title": "CVE-2019-13132 - libzmq5"
    }
  ],
  "scipy": [
    {
        "reason_to_ignore": "The current version of Scipy installed is 1.11.1. Fix requires version to be greater than 1.8.0.", 
        "description":"## Overview\n\nAffected versions of this package are vulnerable to Use After Free via the `Py_FindObjects()` function.\n## PoC\n```\nvoid f() {\n  PyObject *result = PyList_New(1); // <-- new reference returned (line 878)\n  assert(result);\n  printf(\"%ld\\n\", result->ob_refcnt); // 1\n\n  PyErr_NoMemory(); // <-- error happens, an exception is thrown (line 890)\n  Py_XDECREF(result); // <-- destruction here (line 924)\n  printf(\"%ld\\n\", result->ob_refcnt); // 0\n\n  if (PyErr_Occurred()) {\n    Py_XDECREF(result); // <-- use after free here (line 931)\n    printf(\"%ld\\n\", result->ob_refcnt); // -1\n  }\n}\n```\n## Remediation\nUpgrade `scipy` to version 1.8.0 or higher.\n## References\n- [GitHub Commit](https://github.com/scipy/scipy/commit/e32fc2329d3dd23298725153c5b2cc7fcd0f14f1)\n- [GitHub Issue](https://github.com/scipy/scipy/issues/14713)\n- [GitHub PR](https://github.com/scipy/scipy/pull/15013)\n- [GitHub Release](https://github.com/scipy/scipy/releases/tag/v1.8.0rc1)\n- [Report](http://www.square16.org/achievement/cve-2023-29824",
        "vulnerability_id":"SNYK-PYTHON-SCIPY-5759266",
        "name":"SNYK-PYTHON-SCIPY-5759266",
        "package_name":"scipy",
        "package_details":{
          "file_path":"opt/llvm-project/libcxx/utils/google-benchmark/requirements.txt",
          "name":"scipy",
          "package_manager":"PIP",
          "version":"1.5.4",
          "release":null
        },
        "remediation":{
          "recommendation":{
              "text":"None Provided"
          }
        },
        "cvss_v3_score":7.3,
        "cvss_v30_score":0.0,
        "cvss_v31_score":7.3,
        "cvss_v2_score":0.0,
        "cvss_v3_severity":"HIGH",
        "source_url":"https://security.snyk.io/vuln/SNYK-PYTHON-SCIPY-5759266",
        "source":"SNYK",
        "severity":"HIGH",
        "status":"ACTIVE",
        "title":"IN1-PYTHON-SCIPY-5759266 - scipy"
    }
  ]
}
